WARNING  urllib3.connectionpool:connectionpool.py:871 Retrying (Retry(total=2, connect=None, read=None, redirect=None, status=None)) after connection broken by 'ConnectTimeoutError(<urllib3.connection.HTTPConnection object at 0x000002C95AAF9290>, 'Connection to 127.0.0.1 timed out. (connect timeout=1.0)')': /status
WARNING  urllib3.connectionpool:connectionpool.py:871 Retrying (Retry(total=1, connect=None, read=None, redirect=None, status=None)) after connection broken by 'ConnectTimeoutError(<urllib3.connection.HTTPConnection object at 0x000002C95D205C90>, 'Connection to 127.0.0.1 timed out. (connect timeout=1.0)')': /status
WARNING  urllib3.connectionpool:connectionpool.py:871 Retrying (Retry(total=0, connect=None, read=None, redirect=None, status=None)) after connection broken by 'ConnectTimeoutError(<urllib3.connection.HTTPConnection object at 0x000002C95D25C550>, 'Connection to 127.0.0.1 timed out. (connect timeout=1.0)')': /status
WARNING  urllib3.connectionpool:connectionpool.py:871 Retrying (Retry(total=2, connect=None, read=None, redirect=None, status=None)) after connection broken by 'ConnectTimeoutError(<urllib3.connection.HTTPConnection object at 0x000002C95D25D450>, 'Connection to 127.0.0.1 timed out. (connect timeout=1.0)')': /status
WARNING  urllib3.connectionpool:connectionpool.py:871 Retrying (Retry(total=1, connect=None, read=None, redirect=None, status=None)) after connection broken by 'ConnectTimeoutError(<urllib3.connection.HTTPConnection object at 0x000002C95D25DE90>, 'Connection to 127.0.0.1 timed out. (connect timeout=1.0)')': /status
WARNING  urllib3.connectionpool:connectionpool.py:871 Retrying (Retry(total=0, connect=None, read=None, redirect=None, status=None)) after connection broken by 'ConnectTimeoutError(<urllib3.connection.HTTPConnection object at 0x000002C95D25E910>, 'Connection to 127.0.0.1 timed out. (connect timeout=1.0)')': /status
WARNING  urllib3.connectionpool:connectionpool.py:871 Retrying (Retry(total=2, connect=None, read=None, redirect=None, status=None)) after connection broken by 'ConnectTimeoutError(<urllib3.connection.HTTPConnection object at 0x000002C95D25F950>, 'Connection to 127.0.0.1 timed out. (connect timeout=1.0)')': /status
INFO     test_contact:test_add_contact.py:15 clicking on add new contact button
INFO     test_contact:test_add_contact.py:18 Entering Contact's first name
INFO     test_contact:test_add_contact.py:21 Entering Contact's last name
INFO     test_contact:test_add_contact.py:27 Entering phone number
INFO     test_contact:test_add_contact.py:30 Saving Contact